<?xml version="1.0" ?>
<robot xmlns:xacro="http://ros.org/wiki/xacro" name="social_robot">

  <xacro:include filename="$(find social_robot_description)/urdf/social_robot.structure.head.xacro" />
  <xacro:include filename="$(find social_robot_description)/urdf/social_robot.structure.larm.xacro" />
  <xacro:include filename="$(find social_robot_description)/urdf/social_robot.structure.rarm.xacro" />

  <xacro:include filename="$(find social_robot_description)/urdf/social_robot.gazebo.xacro" />
  <xacro:include filename="$(find social_robot_description)/urdf/social_robot.transmissions.xacro" />

<!-- body -->

  <link name="base_footprint"/>

  <joint name="base_link" type="fixed">
    <parent link="base_footprint"/>
    <child link="base_link"/>
    <origin xyz="0.0 0.0 0.020" rpy="0 0 0"/>
  </joint>

  <!-- boll1 -->
  <joint name="boll_1" type="fixed">
    <parent link="base_footprint"/>
    <child link="boll_1"/>
    <origin xyz="0.16 0.16 0.0" rpy="0 0 0"/>
  </joint>
  <link name="boll_1">
    <collision>
      <origin
        xyz="0 0 0"
        rpy="0 0 0" />
      <geometry>
        <sphere radius="0.05"/>
      </geometry>
    </collision>
  </link>
  <!-- boll2 -->
  <joint name="boll_2" type="fixed">
    <parent link="base_footprint"/>
    <child link="boll_2"/>
    <origin xyz="-0.16 0.16 0.0" rpy="0 0 0"/>
  </joint>
  <link name="boll_2">
    <collision>
      <origin
        xyz="0 0 0"
        rpy="0 0 0" />
      <geometry>
        <sphere radius="0.05"/>
      </geometry>
    </collision>
  </link>
  <!-- boll3 -->
  <joint name="boll_3" type="fixed">
    <parent link="base_footprint"/>
    <child link="boll_3"/>
    <origin xyz="0.16 -0.16 0.0" rpy="0 0 0"/>
  </joint>
  <link name="boll_3">
    <collision>
      <origin
        xyz="0 0 0"
        rpy="0 0 0" />
      <geometry>
        <sphere radius="0.05"/>
      </geometry>
    </collision>
  </link>
  <!-- boll4 -->
  <joint name="boll_4" type="fixed">
    <parent link="base_footprint"/>
    <child link="boll_4"/>
    <origin xyz="-0.16 -0.16 0.0" rpy="0 0 0"/>
  </joint>
  <link name="boll_4">
    <collision>
      <origin
        xyz="0 0 0"
        rpy="0 0 0" />
      <geometry>
        <sphere radius="0.05"/>
      </geometry>
    </collision>
  </link>

  <!-- base link -->
  <link name="base_link">
    <inertial>
<!--    <origin
      xyz="-0.160934490597598 8.22653618212244E-06 -0.00189151304431439"
      rpy="0 0 ${pi/2}" />-->
      <origin
        xyz="0.0 0.0 -0.00189151304431439"
        rpy="0 0 ${pi/2}" />
      <mass
        value="9.16468890396806" />
      <inertia
        ixx="1.0e-03"
        ixy="0"
        ixz="0"
        iyy="1.0e-03"
        iyz="0"
        izz="1.0e-03" />
    </inertial>
    <visual>
      <origin
        xyz="0 0 0"
        rpy="0 0 ${pi/2}" />
      <geometry>
        <mesh
          filename="package://social_robot_description/meshes/body/base_link.stl" />
      </geometry>
      <material
        name="">
        <color
          rgba="0.752941176470588 0.752941176470588 0.752941176470588 1" />
      </material>
    </visual>
<!--    <collision>
      <origin
        xyz="0 0 0.165"
        rpy="0 0 ${pi/2}" />
      <geometry>
        <mesh
          filename="package://social_robot_description/meshes/body/base_link.stl" />
       <sphere radius="0.30"/>
      </geometry>
    </collision>-->
  </link>

  <!-- waist roll joint -->
  <joint name="Waist_Roll" type="continuous">
    <origin
      xyz="0 0 0.579000000143115"
      rpy="0 0 0" />
    <parent
      link="base_link" />
    <child
      link="Waist_Roll" />
    <axis
      xyz="1 0 0" />
    <limit effort="30" velocity="1.57" lower="-0.348" upper="0.348" />
    <safety_controller k_velocity="1.57" k_position="15" soft_lower_limit="-0.348" soft_upper_limit="0.348" />
  </joint>
  <xacro:insert_transmission name="Waist_Roll" />

  <!-- waist roll link -->
  <link name="Waist_Roll">
    <inertial>
      <!--<origin
        xyz="-9.28958911114441E-07 -1.6981669084292E-15 0"
        rpy="${pi/2} 0 ${pi/2}" />-->
      <origin
        xyz="0.0 0.0 0"
        rpy="${pi/2} 0 ${pi/2}" />
      <mass
        value="1.43675504024173" />
      <inertia
        ixx="1.0e-03"
        ixy="0"
        ixz="0"
        iyy="1.0e-03"
        iyz="0"
        izz="1.0e-03" />
    </inertial>
    <visual>
      <origin
        xyz="0 0 0"
        rpy="${pi/2} 0 ${pi/2}" />
      <geometry>
        <mesh
          filename="package://social_robot_description/meshes/body/Waist_Roll.stl" />
      </geometry>
      <material
        name="">
        <color
          rgba="0.792156862745098 0.819607843137255 0.933333333333333 1" />
      </material>
    </visual>
   <!-- <collision>
      <origin
        xyz="0 0 0"
        rpy="${pi/2} 0 ${pi/2}" />
      <geometry>
        <mesh
          filename="package://social_robot_description/meshes/body/Waist_Roll.stl" />
      </geometry>
    </collision>-->
  </link>

  <!-- waist pitch joint -->
  <joint name="Waist_Pitch" type="continuous">
    <origin
      xyz="0 0 0"
      rpy="0 0 0" />
    <parent
      link="Waist_Roll" />
    <child
      link="Waist_Pitch" />
    <axis
      xyz="0 1 0" />
    <limit effort="30" velocity="1.57" lower="-0.523" upper="0.523" />
    <safety_controller k_velocity="1.57" k_position="15" soft_lower_limit="-0.523" soft_upper_limit="0.523" />
  </joint>
  <xacro:insert_transmission name="Waist_Pitch" />

  <!-- waist pitch link -->
  <link name="Waist_Pitch">
    <inertial>
      <!--<origin
        xyz="0.101257114843982 1.46815175677656E-05 -0.0180187762940287 "
        rpy="${pi/2} 0 ${pi/2}" />-->
      <origin
        xyz="0.0 0.0 -0.0180187762940287 "
        rpy="${pi/2} 0 ${pi/2}" />
      <mass
        value="2.19862483991908" />
      <inertia
        ixx="1.0e-03"
        ixy="0"
        ixz="0"
        iyy="1.0e-03"
        iyz="0"
        izz="1.0e-03" />
    </inertial>
    <visual>
      <origin
        xyz="0 0 0"
        rpy="${pi/2} 0 ${pi/2}" />
      <geometry>
        <mesh
          filename="package://social_robot_description/meshes/body/Waist_Pitch.stl" />
      </geometry>
      <material
        name="">
        <color
          rgba="0.752941176470588 0.752941176470588 0.752941176470588 1" />
      </material>
    </visual>
<!--    <collision>
      <origin
        xyz="0 0 0"
        rpy="${pi/2} 0 ${pi/2}" />
      <geometry>
        <mesh
          filename="package://social_robot_description/meshes/body/Waist_Pitch.stl" />
      </geometry>
    </collision>-->
  </link>

  <!-- head link -->
  <xacro:social_robot_head parent="Waist_Pitch" />

  <!-- arm link -->
  <xacro:social_robot_l_arm parent="Waist_Pitch" />
  <xacro:social_robot_r_arm parent="Waist_Pitch" />

</robot>
